<?xml version='1.0' encoding='utf-8'?>
<robot name="foosball">
    <link name="Goalkeeper1">
        <inertial>
            <origin xyz="0.00015340748364756963 3.5914001943169186e-05 -0.18004508424272073" rpy="0.0 -3.323448711015916e-65 0.0" />
            <mass value="2.557229041969769" />
            <inertia ixx="0.38935415533121237" iyy="0.38940013412104135" izz="0.00020139230821980547" ixy="-1.1404153811789277e-05" iyz="1.735769355468153e-05" ixz="7.413255870764025e-05" />
        </inertial>
        <visual name="Goalkeeper1_visual">
            <origin xyz="0.0322833670697139 0.1040684565959938 -0.3689999999999988" rpy="1.5707963267948966 -2.453307075453437e-16 -1.3404210330854185" />
            <geometry>
                <mesh filename="meshes/Goalkeeper1.stl" scale="0.001 0.001 0.001" />
            </geometry>
        </visual>
        <collision name="Goalkeeper1_collision">
            <origin xyz="0.0322833670697139 0.1040684565959938 -0.3689999999999988" rpy="1.5707963267948966 -2.453307075453437e-16 -1.3404210330854185" />
            <geometry>
                <cylinder radius="0.02" length="0.1"/>
            </geometry>
        </collision>
    </link>
    <link name="Defense1">
        <inertial>
            <origin xyz="0.00011531397702249535 0.0002871423908008808 -0.18079889479469435" rpy="8.552847072295026e-50 -8.552847072295028e-50 6.588873714519078e-83" />
            <mass value="2.6042699501405315" />
            <inertia ixx="0.38649228641684696" iyy="0.386418132914762" izz="0.0002590803934539032" ixy="-3.547836191641894e-05" iyz="0.0001407489745217094" ixz="5.651942752982197e-05" />
        </inertial>
        <visual name="Defense1_visual">
            <origin xyz="0.022210175787902457 0.055346395375012104 -0.3690000000000002" rpy="1.5707963267948966 -2.715851401832152e-16 -0.38162138706050686" />
            <geometry>
                <mesh filename="meshes/Defense1.stl" scale="0.001 0.001 0.001" />
            </geometry>
        </visual>
        <collision name="Defense1_collision">
            <origin xyz="0.022210175787902457 0.055346395375012104 -0.3690000000000002" rpy="1.5707963267948966 -2.715851401832152e-16 -0.38162138706050686" />
            <geometry>
                <mesh filename="meshes/Defense1.stl" scale="0.001 0.001 0.001" />
            </geometry>
        </collision>
    </link>
    <link name="Attack1">
        <inertial>
            <origin xyz="-0.0003787224626461594 0.0002450765450893044 -0.20179717475549327" rpy="0.0 -0.0 0.0" />
            <mass value="2.6795859185343374" />
            <inertia ixx="0.39841703303988574" iyy="0.3984800863104434" izz="0.00031830223199669216" ixy="7.012707124995354e-05" iyz="0.00011834525894885428" ixz="-0.00018289124334933127" />
        </inertial>
        <visual name="Attack1_visual">
            <origin xyz="-0.07470511982712821 0.048315635568714654 -0.3819999999999987" rpy="1.5707963267948966 -1.926134445299785e-17 0.9967082728099422" />
            <geometry>
                <mesh filename="meshes/Attack1.stl" scale="0.001 0.001 0.001" />
            </geometry>
        </visual>
        <collision name="Attack1_collision">
            <origin xyz="-0.07470511982712821 0.048315635568714654 -0.3819999999999987" rpy="1.5707963267948966 -1.926134445299785e-17 0.9967082728099422" />
            <geometry>
                <mesh filename="meshes/Attack1.stl" scale="0.001 0.001 0.001" />
            </geometry>
        </collision>
    </link>
    <link name="Midfield1">
        <inertial>
            <origin xyz="-0.0007162435062948891 6.0052380756374645e-05 -0.21673168540513332" rpy="3.4211388289180104e-49 -2.138211768073757e-50 0.0" />
            <mass value="2.8029988064909364" />
            <inertia ixx="0.40617198771791124" iyy="0.40642419435206967" izz="0.000434851047428908" ixy="2.1246050582568447e-05" iyz="2.899210025220089e-05" ixz="-0.0003458820630688544" />
        </inertial>
        <visual name="Midfield1_visual">
            <origin xyz="-0.053239948921766755 0.004450157510560402 -0.3531196480970004" rpy="1.5707963267948966 3.3995327602603468e-18 1.487403371349055" />
            <geometry>
                <mesh filename="meshes/Midfield1.stl" scale="0.001 0.001 0.001" />
            </geometry>
        </visual>
        <collision name="Midfield1_collision">
            <origin xyz="-0.053239948921766755 0.004450157510560402 -0.3531196480970004" rpy="1.5707963267948966 3.3995327602603468e-18 1.487403371349055" />
            <geometry>
                <mesh filename="meshes/Midfield1.stl" scale="0.001 0.001 0.001" />
            </geometry>
        </collision>
    </link>
    <link name="Table_Base">
        <inertial>
            <origin xyz="-2.1292360698890524e-17 6.497912810940666e-18 0.242852583175033" rpy="0.0 0.0 0.0" />
            <mass value="87.47950382636654" />
            <inertia ixx="7.830963138833485" iyy="29.723993535094618" izz="35.40218986488285" ixy="-4.669651389122009e-14" iyz="-4.3853229286109475e-17" ixz="-3.730603648675669e-15" />
        </inertial>
        <visual name="Table_Base_visual">
            <origin xyz="0.0 0.0 0.0" rpy="0.0 0.0 0.0" />
            <geometry>
                <mesh filename="meshes/Table_Base.stl" scale="0.001 0.001 0.001" />
            </geometry>
        </visual>
        <collision name="Table_Base_collision" concave="yes">
            <origin xyz="0.0 0.0 0.0" rpy="0.0 0.0 0.0" />
            <geometry>
                <mesh filename="meshes/Table_Base.stl" scale="0.001 0.001 0.001" />
            </geometry>
        </collision>
    </link>
    <link name="Goalkeeper2">
        <inertial>
            <origin xyz="9.237473082642112e-05 0.00012769673994952768 -0.5549488224106098" rpy="0.0 8.352389719038111e-52 0.0" />
            <mass value="2.556411623016105" />
            <inertia ixx="0.3893033306358114" iyy="0.38928727836986343" izz="0.000201332880941818" ixy="-2.440487239252498e-05" iyz="-6.168538253695233e-05" ixz="-4.462583747658066e-05" />
        </inertial>
        <visual name="Goalkeeper2_visual">
            <origin xyz="0.10846446095646883 -0.010388462689574282 -0.36600000000000094" rpy="-1.5707963267948966 2.1294819442707418e-17 2.51493125444228" />
            <geometry>
                <mesh filename="meshes/Goalkeeper2.stl" scale="0.001 0.001 0.001" />
            </geometry>
        </visual>
        <collision name="Goalkeeper2_collision">
            <origin xyz="0.10846446095646883 -0.010388462689574282 -0.36600000000000094" rpy="-1.5707963267948966 2.1294819442707418e-17 2.51493125444228" />
            <geometry>
                <mesh filename="meshes/Goalkeeper2.stl" scale="0.001 0.001 0.001" />
            </geometry>
        </collision>
    </link>
    <link name="Defense2">
        <inertial>
            <origin xyz="-0.0001720787435395721 0.0002552368917284298 -0.550451743395369" rpy="0.0 -0.0 0.0" />
            <mass value="2.6178540728794384" />
            <inertia ixx="0.39353085361105566" iyy="0.39349232813690466" izz="0.00025987650250569594" ixy="4.756482935802664e-05" iyz="-0.00012325805247295762" ixz="8.309494924230165e-05" />
        </inertial>
        <visual name="Defense2_visual">
            <origin xyz="-0.03332489903129002 0.049456713336927506 -0.36600000000000144" rpy="-1.5707963267948968 -3.689894721673184e-19 -2.548654406344247" />
            <geometry>
                <mesh filename="meshes/Defense2.stl" scale="0.001 0.001 0.001" />
            </geometry>
        </visual>
        <collision name="Defense2_collision">
            <origin xyz="-0.03332489903129002 0.049456713336927506 -0.36600000000000144" rpy="-1.5707963267948968 -3.689894721673184e-19 -2.548654406344247" />
            <geometry>
                <mesh filename="meshes/Defense2.stl" scale="0.001 0.001 0.001" />
            </geometry>
        </collision>
    </link>
    <link name="Attack2">
        <inertial>
            <origin xyz="0.00034227673032070525 -0.0002938364452322162 -0.5672028252445063" rpy="0.0 -0.0 0.0" />
            <mass value="2.679585918534337" />
            <inertia ixx="0.39843694618384845" iyy="0.39846017316648197" izz="0.0003183022319967477" ixy="7.600566869381264e-05" iyz="0.00014190015744164342" ixz="-0.00016528506444211943" />
        </inertial>
        <visual name="Attack2_visual">
            <origin xyz="0.06749002281722921 -0.05796854654831669 -0.3870000000000005" rpy="-1.5707963267948966 -3.4784580259060044e-17 0.8611463455474737" />
            <geometry>
                <mesh filename="meshes/Attack2.stl" scale="0.001 0.001 0.001" />
            </geometry>
        </visual>
        <collision name="Attack2_collision">
            <origin xyz="0.06749002281722921 -0.05796854654831669 -0.3870000000000005" rpy="-1.5707963267948966 -3.4784580259060044e-17 0.8611463455474737" />
            <geometry>
                <mesh filename="meshes/Attack2.stl" scale="0.001 0.001 0.001" />
            </geometry>
        </collision>
    </link>
    <link name="Midfield2">
        <inertial>
            <origin xyz="0.0007187179995420756 -7.448884295016001e-06 -0.5502683145948761" rpy="0.0 -0.0 3.851859888774472e-34" />
            <mass value="2.802998806490934" />
            <inertia ixx="0.4061702389523836" iyy="0.406425943117605" izz="0.0004348510474288524" ixy="2.699299038706065e-06" iyz="3.604986792221653e-06" ixz="-0.00034707628484089554" />
        </inertial>
        <visual name="Midfield2_visual">
            <origin xyz="0.05342260041270155 -0.0005672990444980286 -0.41388035190300526" rpy="-1.5707963267948999 1.6449927125210362e-15 1.5601776426098097" />
            <geometry>
                <mesh filename="meshes/Midfield2.stl" scale="0.001 0.001 0.001" />
            </geometry>
        </visual>
        <collision name="Midfield2_collision">
            <origin xyz="0.05342260041270155 -0.0005672990444980286 -0.41388035190300526" rpy="-1.5707963267948999 1.6449927125210362e-15 1.5601776426098097" />
            <geometry>
                <mesh filename="meshes/Midfield2.stl" scale="0.001 0.001 0.001" />
            </geometry>
        </collision>
    </link>
    <link name="Goalkeeper2_vir">
        <inertial>
            <origin xyz="0.0 -2.842170943040401e-16 -0.006651214066486659" rpy="0.0 -0.0 0.0" />
            <mass value="0.0004289781164884129" />
            <inertia ixx="7.711237889711491e-09" iyy="8.157572822374993e-09" izz="3.2172026207097273e-09" ixy="6.791714526931461e-10" iyz="6.776263578034403e-21" ixz="0.0" />
        </inertial>
        <visual name="Goalkeeper2_vir_visual">
            <origin xyz="0.22268937978500647 -0.5099999335774679 0.10242535711913661" rpy="1.5707963267948966 4.523894771968062e-18 2.51493125444228" />
            <geometry>
                <mesh filename="meshes/Goalkeeper2_vir.stl" scale="0.001 0.001 0.001" />
            </geometry>
        </visual>
        <collision name="Goalkeeper2_vir_collision">
            <origin xyz="0.22268937978500647 -0.5099999335774679 0.10242535711913661" rpy="1.5707963267948966 4.523894771968062e-18 2.51493125444228" />
            <geometry>
                <mesh filename="meshes/Goalkeeper2_vir.stl" scale="0.001 0.001 0.001" />
            </geometry>
        </collision>
    </link>
    <link name="Defense2_vir">
        <inertial>
            <origin xyz="0.0 0.0 -0.006651214066486659" rpy="0.0 -0.0 0.0" />
            <mass value="0.0004289781164884129" />
            <inertia ixx="7.665972409938286e-09" iyy="8.202838302161751e-09" izz="3.217202620750385e-09" ixy="-6.625868498818014e-10" iyz="1.3552527156068805e-20" ixz="-1.3552527156068805e-20" />
        </inertial>
        <visual name="Defense2_vir_visual">
            <origin xyz="0.5554803821761098 0.03364575954760255 0.10242535711913661" rpy="1.5707963267948966 -5.5116381480099175e-19 -2.548654406344247" />
            <geometry>
                <mesh filename="meshes/Defense2_vir.stl" scale="0.001 0.001 0.001" />
            </geometry>
        </visual>
        <collision name="Defense2_vir_collision">
            <origin xyz="0.5554803821761098 0.03364575954760255 0.10242535711913661" rpy="1.5707963267948966 -5.5116381480099175e-19 -2.548654406344247" />
            <geometry>
                <mesh filename="meshes/Defense2_vir.stl" scale="0.001 0.001 0.001" />
            </geometry>
        </collision>
    </link>
    <link name="Attack1_vir">
        <inertial>
            <origin xyz="-1.0658141036401502e-16 0.0 -0.006651214066486518" rpy="0.0 -0.0 0.0" />
            <mass value="0.0004289781164884129" />
            <inertia ixx="8.227621423585415e-09" iyy="7.641189288311334e-09" izz="3.217202622525766e-09" ixy="-6.519984032448485e-10" iyz="6.776263578034403e-21" ixz="0.0" />
        </inertial>
        <visual name="Attack1_vir_visual">
            <origin xyz="-0.49759315386363595 -0.2491817516313906 0.10242535711913675" rpy="1.5707963267948966 -2.7571148672760934e-17 0.9967082728099422" />
            <geometry>
                <mesh filename="meshes/Attack1_vir.stl" scale="0.001 0.001 0.001" />
            </geometry>
        </visual>
        <collision name="Attack1_vir_collision">
            <origin xyz="-0.49759315386363595 -0.2491817516313906 0.10242535711913675" rpy="1.5707963267948966 -2.7571148672760934e-17 0.9967082728099422" />
            <geometry>
                <mesh filename="meshes/Attack1_vir.stl" scale="0.001 0.001 0.001" />
            </geometry>
        </collision>
    </link>
    <link name="Midfield2_vir">
        <inertial>
            <origin xyz="-2.486899575160351e-16 -7.105427357601002e-17 -0.006651214066486659" rpy="0.0 -0.0 0.0" />
            <mass value="0.0004289781164884129" />
            <inertia ixx="8.649141046082479e-09" iyy="7.219669667000116e-09" izz="3.21720261635259e-09" ixy="-1.518138790203229e-11" iyz="-2.0328790734103208e-19" ixz="2.0837010502455788e-19" />
        </inertial>
        <visual name="Midfield2_vir_visual">
            <origin xyz="-0.2875752379703344 -0.47643569831023824 0.10242535711913625" rpy="1.570796326794895 1.4472939232271576e-15 1.5601776426098097" />
            <geometry>
                <mesh filename="meshes/Midfield2_vir.stl" scale="0.001 0.001 0.001" />
            </geometry>
        </visual>
        <collision name="Midfield2_vir_collision">
            <origin xyz="-0.2875752379703344 -0.47643569831023824 0.10242535711913625" rpy="1.570796326794895 1.4472939232271576e-15 1.5601776426098097" />
            <geometry>
                <mesh filename="meshes/Midfield2_vir.stl" scale="0.001 0.001 0.001" />
            </geometry>
        </collision>
    </link>
    <link name="Midfield1_vir">
        <inertial>
            <origin xyz="-7.105427357601002e-17 -7.105427357601002e-17 -0.006651214066486659" rpy="0.0 -0.0 0.0" />
            <mass value="0.0004289781164884129" />
            <inertia ixx="8.639381949732973e-09" iyy="7.229428762238314e-09" izz="3.2172026217193905e-09" ixy="-1.186826965118181e-10" iyz="0.0" ixz="5.082197683525802e-21" />
        </inertial>
        <visual name="Midfield1_vir_visual">
            <origin xyz="-0.3214557254267655 -0.45426502034429406 0.10242535711913661" rpy="1.5707963267948966 4.800841154137654e-18 1.4874033713490553" />
            <geometry>
                <mesh filename="meshes/Midfield1_vir.stl" scale="0.001 0.001 0.001" />
            </geometry>
        </visual>
        <collision name="Midfield1_vir_collision">
            <origin xyz="-0.3214557254267655 -0.45426502034429406 0.10242535711913661" rpy="1.5707963267948966 4.800841154137654e-18 1.4874033713490553" />
            <geometry>
                <mesh filename="meshes/Midfield1_vir.stl" scale="0.001 0.001 0.001" />
            </geometry>
        </collision>
    </link>
    <link name="Attack2_vir">
        <inertial>
            <origin xyz="-1.4210854715202004e-16 0.0 -0.006651214066486659" rpy="0.0 -0.0 0.0" />
            <mass value="0.0004289781164884129" />
            <inertia ixx="8.0422958280039e-09" iyy="7.826514884001269e-09" izz="3.2172026213060385e-09" ixy="-7.067087279960527e-10" iyz="1.3552527156068805e-20" ixz="0.0" />
        </inertial>
        <visual name="Attack2_vir_visual">
            <origin xyz="-0.526704199917905 -0.1796473709991063 0.10242535711913661" rpy="1.5707963267948966 -1.3832167825539804e-17 0.8611463455474737" />
            <geometry>
                <mesh filename="meshes/Attack2_vir.stl" scale="0.001 0.001 0.001" />
            </geometry>
        </visual>
        <collision name="Attack2_vir_collision">
            <origin xyz="-0.526704199917905 -0.1796473709991063 0.10242535711913661" rpy="1.5707963267948966 -1.3832167825539804e-17 0.8611463455474737" />
            <geometry>
                <mesh filename="meshes/Attack2_vir.stl" scale="0.001 0.001 0.001" />
            </geometry>
        </collision>
    </link>
    <link name="Defense1_vir">
        <inertial>
            <origin xyz="-7.105427357601002e-17 0.0 -0.006651214066486659" rpy="0.0 -0.0 0.0" />
            <mass value="0.0004289781164884129" />
            <inertia ixx="7.4178221509029266e-09" iyy="8.450988561170005e-09" izz="3.2172026209672253e-09" ixy="4.94185564696339e-10" iyz="1.3552527156068805e-20" ixz="0.0" />
        </inertial>
        <visual name="Defense1_vir_visual">
            <origin xyz="-0.3397606240010066 0.4407416595881291 0.10242535711913661" rpy="1.5707963267948966 -5.308770865625231e-18 -0.3816213870605068" />
            <geometry>
                <mesh filename="meshes/Defense1_vir.stl" scale="0.001 0.001 0.001" />
            </geometry>
        </visual>
        <collision name="Defense1_vir_collision">
            <origin xyz="-0.3397606240010066 0.4407416595881291 0.10242535711913661" rpy="1.5707963267948966 -5.308770865625231e-18 -0.3816213870605068" />
            <geometry>
                <mesh filename="meshes/Defense1_vir.stl" scale="0.001 0.001 0.001" />
            </geometry>
        </collision>
    </link>
    <link name="Goalkeeper1_vir">
        <inertial>
            <origin xyz="-1.4210854715202004e-16 7.105427357601002e-17 -0.006651214066486518" rpy="0.0 -0.0 0.0" />
            <mass value="0.0004289781164884129" />
            <inertia ixx="8.574752110600595e-09" iyy="7.294058601363916e-09" izz="3.217202622498661e-09" ixy="3.1785785192339853e-10" iyz="0.0" ixz="1.3552527156068805e-20" />
        </inertial>
        <visual name="Goalkeeper1_vir_visual">
            <origin xyz="0.165554711588606 0.5313022958625923 0.10242535711913675" rpy="1.5707963267948966 -1.2557393277891349e-32 -1.3404210330854185" />
            <geometry>
                <mesh filename="meshes/Goalkeeper1_vir.stl" scale="0.001 0.001 0.001" />
            </geometry>
        </visual>
        <collision name="Goalkeeper1_vir_collision">
            <origin xyz="0.165554711588606 0.5313022958625923 0.10242535711913675" rpy="1.5707963267948966 -1.2557393277891349e-32 -1.3404210330854185" />
            <geometry>
                <mesh filename="meshes/Goalkeeper1_vir.stl" scale="0.001 0.001 0.001" />
            </geometry>
        </collision>
    </link>
    <joint name="Table_Base_goal2_rev" type="continuous">
        <origin xyz="0.525 0.270 0.360" rpy="-1.5707963268 -0.0000000000 0.0000000000" />
        <parent link="Table_Base" />
        <child link="Goalkeeper2_vir" />
        <axis xyz="0.0 0.0 1.0" />
    </joint>
    <joint name="Table_Base_defense2_rev" type="continuous">
        <origin xyz="0.375 0.270 0.360" rpy="-1.5707963268 -0.0000000000 0.0000000000" />
        <parent link="Table_Base" />
        <child link="Defense2_vir" />
        <axis xyz="0.0 0.0 1.0" />
        <limit lower="-3.141593" upper="3.141593" effort="1000000" velocity="1000000" />
    </joint>
    <joint name="Table_Base_attack1_rev" type="continuous">
        <origin xyz="0.225 0.270 0.360" rpy="-1.5707963268 -0.0000000000 0.0000000000" />
        <parent link="Table_Base" />
        <child link="Attack1_vir" />
        <axis xyz="0.0 0.0 1.0" />
        <limit lower="-3.141593" upper="3.141593" effort="1000000" velocity="1000000" />
    </joint>
    <joint name="Table_Base_midfield2_rev" type="continuous">
        <origin xyz="0.075 0.270 0.360" rpy="-1.5707963268 -0.0000000000 0.0000000000" />
        <parent link="Table_Base" />
        <child link="Midfield2_vir" />
        <axis xyz="0.0 0.0 1.0" />
        <limit lower="-3.141593" upper="3.141593" effort="1000000" velocity="1000000" />
    </joint>
    <joint name="Table_Base_midfield1_rev" type="continuous">
        <origin xyz="-0.075 0.270 0.360" rpy="-1.5707963268 -0.0000000000 0.0000000000" />
        <parent link="Table_Base" />
        <child link="Midfield1_vir" />
        <axis xyz="0.0 0.0 1.0" />
        <limit lower="-3.141593" upper="3.141593" effort="1000000" velocity="1000000" />
    </joint>
    <joint name="Table_Base_attack2_rev" type="continuous">
        <origin xyz="-0.225 0.270 0.360" rpy="-1.5707963268 -0.0000000000 0.0000000000" />
        <parent link="Table_Base" />
        <child link="Attack2_vir" />
        <axis xyz="0.0 0.0 1.0" />
        <limit lower="-3.141593" upper="3.141593" effort="1000000" velocity="1000000" />
    </joint>
    <joint name="Table_Base_defense1_rev" type="continuous">
        <origin xyz="-0.375 0.270 0.360" rpy="-1.5707963268 -0.0000000000 0.0000000000" />
        <parent link="Table_Base" />
        <child link="Defense1_vir" />
        <axis xyz="0.0 0.0 1.0" />
        <limit lower="-3.141593" upper="3.141593" effort="1000000" velocity="1000000" />
    </joint>
    <joint name="Table_Base_goal1_rev" type="continuous">
        <origin xyz="-0.525 0.270 0.360" rpy="-1.5707963268 -0.0000000000 0.0000000000" />
        <parent link="Table_Base" />
        <child link="Goalkeeper1_vir" />
        <axis xyz="0.0 0.0 1.0" />
        <limit lower="-3.141593" upper="3.141593" effort="1000000" velocity="1000000" />
    </joint>
    <joint name="Defense2_vir_defense2_slide" type="prismatic">
        <origin xyz="0.0 0.0 0.0" rpy="-4.664361584062837e-35 -1.6687317804273193e-34 0.0" />
        <parent link="Defense2_vir" />
        <child link="Defense2" />
        <axis xyz="1.6687317804273193e-34 -4.664361584062837e-35 1.0" />
        <limit lower="-0.060" upper="0.260" effort="1000000" velocity="1000000" />
    </joint>
    <joint name="Attack1_vir_attack1_slide" type="prismatic">
        <origin xyz="0.0 0.0 0.0" rpy="3.0814879110195774e-33 5.200010849845537e-33 0.0" />
        <parent link="Attack1_vir" />
        <child link="Attack1" />
        <axis xyz="-5.200010849845537e-33 3.0814879110195774e-33 1.0" />
        <limit lower="0.000" upper="0.200" effort="1000000" velocity="1000000" />
    </joint>
    <joint name="Midfield2_vir_midfield2_slide" type="prismatic">
        <origin xyz="0.0 0.0 0.0" rpy="6.471124613141114e-32 -0.0 1.7347234759768075e-18" />
        <parent link="Midfield2_vir" />
        <child link="Midfield2" />
        <axis xyz="0.0 6.471124613141112e-32 0.9999999999999999" />
        <limit lower="0.040" upper="0.170" effort="1000000" velocity="1000000" />
    </joint>
    <joint name="Midfield1_vir_midfield1_slide" type="prismatic">
        <origin xyz="0.0 0.0 0.0" rpy="1.7333369499485123e-33 -1.9259299443872363e-34 0.0" />
        <parent link="Midfield1_vir" />
        <child link="Midfield1" />
        <axis xyz="1.925929944387236e-34 1.7333369499485123e-33 1.0" />
        <limit lower="0.040" upper="0.170" effort="1000000" velocity="1000000" />
    </joint>
    <joint name="Attack2_vir_attack2_slide" type="prismatic">
        <origin xyz="0.0 0.0 0.0" rpy="-1.925929944387236e-34 7.703719777548943e-34 0.0" />
        <parent link="Attack2_vir" />
        <child link="Attack2" />
        <axis xyz="-7.703719777548943e-34 -1.925929944387236e-34 1.0" />
        <limit lower="0.000" upper="0.200" effort="1000000" velocity="1000000" />
    </joint>
    <joint name="Defense1_vir_defense1_slide" type="prismatic">
        <origin xyz="0.0 0.0 0.0" rpy="7.703719777548943e-34 -5.777789833161708e-34 0.0" />
        <parent link="Defense1_vir" />
        <child link="Defense1" />
        <axis xyz="5.7777898331617076e-34 7.703719777548943e-34 1.0" />
        <limit lower="-0.060" upper="0.260" effort="1000000" velocity="1000000" />
    </joint>
    <joint name="Goalkeeper1_vir_goal1_slide" type="prismatic">
        <origin xyz="0.0 0.0 0.0" rpy="-2.309268709519657e-47 4.105366594701612e-48 2.7755575615628907e-17" />
        <parent link="Goalkeeper1_vir" />
        <child link="Goalkeeper1" />
        <axis xyz="-4.1053665947016125e-48 -2.309268709519657e-47 1.0" />
        <limit lower="0.000" upper="0.200" effort="1000000" velocity="1000000" />
    </joint>
    <joint name="Goalkeeper2_vir_goal2_slide" type="prismatic">
        <origin xyz="0.0 0.0 0.0" rpy="4.664361584062837e-34 1.9560225997682864e-35 -5.551115123125783e-17" />
        <parent link="Goalkeeper2_vir" />
        <child link="Goalkeeper2" />
        <axis xyz="-1.9560225997682864e-35 4.664361584062837e-34 1.0" />
        <limit lower="0.000" upper="0.200" effort="1000000" velocity="1000000" />
    </joint>
</robot>
